AXES: BEGIN version 6.1.0, blocking by ip_address
Watching for file changes with StatReloader
Unable to import numpy
Traceback (most recent call last):
  File "C:\Users\Roark\OneDrive\Documentos\SPP2\spp-django\venv\Lib\site-packages\mip\ndarray.py", line 6, in <module>
    import numpy as np
ModuleNotFoundError: No module named 'numpy'
Numpy not available
Traceback (most recent call last):
  File "C:\Users\Roark\OneDrive\Documentos\SPP2\spp-django\venv\Lib\site-packages\mip\model.py", line 12, in <module>
    import numpy as np
ModuleNotFoundError: No module named 'numpy'
Using Python-MIP package version 1.15.0
C:\Users\Roark\OneDrive\Documentos\SPP2\SPP-Django\core\views.py changed, reloading.
AXES: BEGIN version 6.1.0, blocking by ip_address
Watching for file changes with StatReloader
Unable to import numpy
Traceback (most recent call last):
  File "C:\Users\Roark\OneDrive\Documentos\SPP2\spp-django\venv\Lib\site-packages\mip\ndarray.py", line 6, in <module>
    import numpy as np
ModuleNotFoundError: No module named 'numpy'
Numpy not available
Traceback (most recent call last):
  File "C:\Users\Roark\OneDrive\Documentos\SPP2\spp-django\venv\Lib\site-packages\mip\model.py", line 12, in <module>
    import numpy as np
ModuleNotFoundError: No module named 'numpy'
Using Python-MIP package version 1.15.0
('23000', "[23000] [Microsoft][ODBC Driver 17 for SQL Server][SQL Server]Cannot insert the value NULL into column 'cliente', table 'SPPDB2.0.dbo.core_pedido'; column does not allow nulls. INSERT fails. (515) (SQLExecDirectW); [23000] [Microsoft][ODBC Driver 17 for SQL Server][SQL Server]The statement has been terminated. (3621)")
Traceback (most recent call last):
  File "C:\Users\Roark\OneDrive\Documentos\SPP2\spp-django\venv\Lib\site-packages\django\db\backends\utils.py", line 89, in _execute
    return self.cursor.execute(sql, params)
           ^^^^^^^^^^^^^^^^^^^^^^^^^^^^^^^^
  File "C:\Users\Roark\OneDrive\Documentos\SPP2\spp-django\venv\Lib\site-packages\mssql\base.py", line 621, in execute
    return self.cursor.execute(sql, params)
           ^^^^^^^^^^^^^^^^^^^^^^^^^^^^^^^^
pyodbc.IntegrityError: ('23000', "[23000] [Microsoft][ODBC Driver 17 for SQL Server][SQL Server]Cannot insert the value NULL into column 'cliente', table 'SPPDB2.0.dbo.core_pedido'; column does not allow nulls. INSERT fails. (515) (SQLExecDirectW); [23000] [Microsoft][ODBC Driver 17 for SQL Server][SQL Server]The statement has been terminated. (3621)")

The above exception was the direct cause of the following exception:

Traceback (most recent call last):
  File "C:\Users\Roark\OneDrive\Documentos\SPP2\spp-django\venv\Lib\site-packages\import_export\resources.py", line 748, in import_row
    self.save_instance(instance, new, using_transactions, dry_run)
  File "C:\Users\Roark\OneDrive\Documentos\SPP2\spp-django\venv\Lib\site-packages\import_export\resources.py", line 491, in save_instance
    instance.save()
  File "C:\Users\Roark\OneDrive\Documentos\SPP2\spp-django\venv\Lib\site-packages\django\db\models\base.py", line 814, in save
    self.save_base(
  File "C:\Users\Roark\OneDrive\Documentos\SPP2\spp-django\venv\Lib\site-packages\django\db\models\base.py", line 877, in save_base
    updated = self._save_table(
              ^^^^^^^^^^^^^^^^^
  File "C:\Users\Roark\OneDrive\Documentos\SPP2\spp-django\venv\Lib\site-packages\django\db\models\base.py", line 1020, in _save_table
    results = self._do_insert(
              ^^^^^^^^^^^^^^^^
  File "C:\Users\Roark\OneDrive\Documentos\SPP2\spp-django\venv\Lib\site-packages\django\db\models\base.py", line 1061, in _do_insert
    return manager._insert(
           ^^^^^^^^^^^^^^^^
  File "C:\Users\Roark\OneDrive\Documentos\SPP2\spp-django\venv\Lib\site-packages\django\db\models\manager.py", line 87, in manager_method
    return getattr(self.get_queryset(), name)(*args, **kwargs)
           ^^^^^^^^^^^^^^^^^^^^^^^^^^^^^^^^^^^^^^^^^^^^^^^^^^^
  File "C:\Users\Roark\OneDrive\Documentos\SPP2\spp-django\venv\Lib\site-packages\django\db\models\query.py", line 1805, in _insert
    return query.get_compiler(using=using).execute_sql(returning_fields)
           ^^^^^^^^^^^^^^^^^^^^^^^^^^^^^^^^^^^^^^^^^^^^^^^^^^^^^^^^^^^^^
  File "C:\Users\Roark\OneDrive\Documentos\SPP2\spp-django\venv\Lib\site-packages\django\db\models\sql\compiler.py", line 1822, in execute_sql
    cursor.execute(sql, params)
  File "C:\Users\Roark\OneDrive\Documentos\SPP2\spp-django\venv\Lib\site-packages\django\db\backends\utils.py", line 102, in execute
    return super().execute(sql, params)
           ^^^^^^^^^^^^^^^^^^^^^^^^^^^^
  File "C:\Users\Roark\OneDrive\Documentos\SPP2\spp-django\venv\Lib\site-packages\django\db\backends\utils.py", line 67, in execute
    return self._execute_with_wrappers(
           ^^^^^^^^^^^^^^^^^^^^^^^^^^^^
  File "C:\Users\Roark\OneDrive\Documentos\SPP2\spp-django\venv\Lib\site-packages\django\db\backends\utils.py", line 80, in _execute_with_wrappers
    return executor(sql, params, many, context)
           ^^^^^^^^^^^^^^^^^^^^^^^^^^^^^^^^^^^^
  File "C:\Users\Roark\OneDrive\Documentos\SPP2\spp-django\venv\Lib\site-packages\django\db\backends\utils.py", line 84, in _execute
    with self.db.wrap_database_errors:
  File "C:\Users\Roark\OneDrive\Documentos\SPP2\spp-django\venv\Lib\site-packages\django\db\utils.py", line 91, in __exit__
    raise dj_exc_value.with_traceback(traceback) from exc_value
  File "C:\Users\Roark\OneDrive\Documentos\SPP2\spp-django\venv\Lib\site-packages\django\db\backends\utils.py", line 89, in _execute
    return self.cursor.execute(sql, params)
           ^^^^^^^^^^^^^^^^^^^^^^^^^^^^^^^^
  File "C:\Users\Roark\OneDrive\Documentos\SPP2\spp-django\venv\Lib\site-packages\mssql\base.py", line 621, in execute
    return self.cursor.execute(sql, params)
           ^^^^^^^^^^^^^^^^^^^^^^^^^^^^^^^^
django.db.utils.IntegrityError: ('23000', "[23000] [Microsoft][ODBC Driver 17 for SQL Server][SQL Server]Cannot insert the value NULL into column 'cliente', table 'SPPDB2.0.dbo.core_pedido'; column does not allow nulls. INSERT fails. (515) (SQLExecDirectW); [23000] [Microsoft][ODBC Driver 17 for SQL Server][SQL Server]The statement has been terminated. (3621)")
('23000', "[23000] [Microsoft][ODBC Driver 17 for SQL Server][SQL Server]Cannot insert the value NULL into column 'cliente', table 'SPPDB2.0.dbo.core_pedido'; column does not allow nulls. INSERT fails. (515) (SQLExecDirectW); [23000] [Microsoft][ODBC Driver 17 for SQL Server][SQL Server]The statement has been terminated. (3621)")
Traceback (most recent call last):
  File "C:\Users\Roark\OneDrive\Documentos\SPP2\spp-django\venv\Lib\site-packages\django\db\backends\utils.py", line 89, in _execute
    return self.cursor.execute(sql, params)
           ^^^^^^^^^^^^^^^^^^^^^^^^^^^^^^^^
  File "C:\Users\Roark\OneDrive\Documentos\SPP2\spp-django\venv\Lib\site-packages\mssql\base.py", line 621, in execute
    return self.cursor.execute(sql, params)
           ^^^^^^^^^^^^^^^^^^^^^^^^^^^^^^^^
pyodbc.IntegrityError: ('23000', "[23000] [Microsoft][ODBC Driver 17 for SQL Server][SQL Server]Cannot insert the value NULL into column 'cliente', table 'SPPDB2.0.dbo.core_pedido'; column does not allow nulls. INSERT fails. (515) (SQLExecDirectW); [23000] [Microsoft][ODBC Driver 17 for SQL Server][SQL Server]The statement has been terminated. (3621)")

The above exception was the direct cause of the following exception:

Traceback (most recent call last):
  File "C:\Users\Roark\OneDrive\Documentos\SPP2\spp-django\venv\Lib\site-packages\import_export\resources.py", line 748, in import_row
    self.save_instance(instance, new, using_transactions, dry_run)
  File "C:\Users\Roark\OneDrive\Documentos\SPP2\spp-django\venv\Lib\site-packages\import_export\resources.py", line 491, in save_instance
    instance.save()
  File "C:\Users\Roark\OneDrive\Documentos\SPP2\spp-django\venv\Lib\site-packages\django\db\models\base.py", line 814, in save
    self.save_base(
  File "C:\Users\Roark\OneDrive\Documentos\SPP2\spp-django\venv\Lib\site-packages\django\db\models\base.py", line 877, in save_base
    updated = self._save_table(
              ^^^^^^^^^^^^^^^^^
  File "C:\Users\Roark\OneDrive\Documentos\SPP2\spp-django\venv\Lib\site-packages\django\db\models\base.py", line 1020, in _save_table
    results = self._do_insert(
              ^^^^^^^^^^^^^^^^
  File "C:\Users\Roark\OneDrive\Documentos\SPP2\spp-django\venv\Lib\site-packages\django\db\models\base.py", line 1061, in _do_insert
    return manager._insert(
           ^^^^^^^^^^^^^^^^
  File "C:\Users\Roark\OneDrive\Documentos\SPP2\spp-django\venv\Lib\site-packages\django\db\models\manager.py", line 87, in manager_method
    return getattr(self.get_queryset(), name)(*args, **kwargs)
           ^^^^^^^^^^^^^^^^^^^^^^^^^^^^^^^^^^^^^^^^^^^^^^^^^^^
  File "C:\Users\Roark\OneDrive\Documentos\SPP2\spp-django\venv\Lib\site-packages\django\db\models\query.py", line 1805, in _insert
    return query.get_compiler(using=using).execute_sql(returning_fields)
           ^^^^^^^^^^^^^^^^^^^^^^^^^^^^^^^^^^^^^^^^^^^^^^^^^^^^^^^^^^^^^
  File "C:\Users\Roark\OneDrive\Documentos\SPP2\spp-django\venv\Lib\site-packages\django\db\models\sql\compiler.py", line 1822, in execute_sql
    cursor.execute(sql, params)
  File "C:\Users\Roark\OneDrive\Documentos\SPP2\spp-django\venv\Lib\site-packages\django\db\backends\utils.py", line 102, in execute
    return super().execute(sql, params)
           ^^^^^^^^^^^^^^^^^^^^^^^^^^^^
  File "C:\Users\Roark\OneDrive\Documentos\SPP2\spp-django\venv\Lib\site-packages\django\db\backends\utils.py", line 67, in execute
    return self._execute_with_wrappers(
           ^^^^^^^^^^^^^^^^^^^^^^^^^^^^
  File "C:\Users\Roark\OneDrive\Documentos\SPP2\spp-django\venv\Lib\site-packages\django\db\backends\utils.py", line 80, in _execute_with_wrappers
    return executor(sql, params, many, context)
           ^^^^^^^^^^^^^^^^^^^^^^^^^^^^^^^^^^^^
  File "C:\Users\Roark\OneDrive\Documentos\SPP2\spp-django\venv\Lib\site-packages\django\db\backends\utils.py", line 84, in _execute
    with self.db.wrap_database_errors:
  File "C:\Users\Roark\OneDrive\Documentos\SPP2\spp-django\venv\Lib\site-packages\django\db\utils.py", line 91, in __exit__
    raise dj_exc_value.with_traceback(traceback) from exc_value
  File "C:\Users\Roark\OneDrive\Documentos\SPP2\spp-django\venv\Lib\site-packages\django\db\backends\utils.py", line 89, in _execute
    return self.cursor.execute(sql, params)
           ^^^^^^^^^^^^^^^^^^^^^^^^^^^^^^^^
  File "C:\Users\Roark\OneDrive\Documentos\SPP2\spp-django\venv\Lib\site-packages\mssql\base.py", line 621, in execute
    return self.cursor.execute(sql, params)
           ^^^^^^^^^^^^^^^^^^^^^^^^^^^^^^^^
django.db.utils.IntegrityError: ('23000', "[23000] [Microsoft][ODBC Driver 17 for SQL Server][SQL Server]Cannot insert the value NULL into column 'cliente', table 'SPPDB2.0.dbo.core_pedido'; column does not allow nulls. INSERT fails. (515) (SQLExecDirectW); [23000] [Microsoft][ODBC Driver 17 for SQL Server][SQL Server]The statement has been terminated. (3621)")
('23000', "[23000] [Microsoft][ODBC Driver 17 for SQL Server][SQL Server]Cannot insert the value NULL into column 'cliente', table 'SPPDB2.0.dbo.core_pedido'; column does not allow nulls. INSERT fails. (515) (SQLExecDirectW); [23000] [Microsoft][ODBC Driver 17 for SQL Server][SQL Server]The statement has been terminated. (3621)")
Traceback (most recent call last):
  File "C:\Users\Roark\OneDrive\Documentos\SPP2\spp-django\venv\Lib\site-packages\django\db\backends\utils.py", line 89, in _execute
    return self.cursor.execute(sql, params)
           ^^^^^^^^^^^^^^^^^^^^^^^^^^^^^^^^
  File "C:\Users\Roark\OneDrive\Documentos\SPP2\spp-django\venv\Lib\site-packages\mssql\base.py", line 621, in execute
    return self.cursor.execute(sql, params)
           ^^^^^^^^^^^^^^^^^^^^^^^^^^^^^^^^
pyodbc.IntegrityError: ('23000', "[23000] [Microsoft][ODBC Driver 17 for SQL Server][SQL Server]Cannot insert the value NULL into column 'cliente', table 'SPPDB2.0.dbo.core_pedido'; column does not allow nulls. INSERT fails. (515) (SQLExecDirectW); [23000] [Microsoft][ODBC Driver 17 for SQL Server][SQL Server]The statement has been terminated. (3621)")

The above exception was the direct cause of the following exception:

Traceback (most recent call last):
  File "C:\Users\Roark\OneDrive\Documentos\SPP2\spp-django\venv\Lib\site-packages\import_export\resources.py", line 748, in import_row
    self.save_instance(instance, new, using_transactions, dry_run)
  File "C:\Users\Roark\OneDrive\Documentos\SPP2\spp-django\venv\Lib\site-packages\import_export\resources.py", line 491, in save_instance
    instance.save()
  File "C:\Users\Roark\OneDrive\Documentos\SPP2\spp-django\venv\Lib\site-packages\django\db\models\base.py", line 814, in save
    self.save_base(
  File "C:\Users\Roark\OneDrive\Documentos\SPP2\spp-django\venv\Lib\site-packages\django\db\models\base.py", line 877, in save_base
    updated = self._save_table(
              ^^^^^^^^^^^^^^^^^
  File "C:\Users\Roark\OneDrive\Documentos\SPP2\spp-django\venv\Lib\site-packages\django\db\models\base.py", line 1020, in _save_table
    results = self._do_insert(
              ^^^^^^^^^^^^^^^^
  File "C:\Users\Roark\OneDrive\Documentos\SPP2\spp-django\venv\Lib\site-packages\django\db\models\base.py", line 1061, in _do_insert
    return manager._insert(
           ^^^^^^^^^^^^^^^^
  File "C:\Users\Roark\OneDrive\Documentos\SPP2\spp-django\venv\Lib\site-packages\django\db\models\manager.py", line 87, in manager_method
    return getattr(self.get_queryset(), name)(*args, **kwargs)
           ^^^^^^^^^^^^^^^^^^^^^^^^^^^^^^^^^^^^^^^^^^^^^^^^^^^
  File "C:\Users\Roark\OneDrive\Documentos\SPP2\spp-django\venv\Lib\site-packages\django\db\models\query.py", line 1805, in _insert
    return query.get_compiler(using=using).execute_sql(returning_fields)
           ^^^^^^^^^^^^^^^^^^^^^^^^^^^^^^^^^^^^^^^^^^^^^^^^^^^^^^^^^^^^^
  File "C:\Users\Roark\OneDrive\Documentos\SPP2\spp-django\venv\Lib\site-packages\django\db\models\sql\compiler.py", line 1822, in execute_sql
    cursor.execute(sql, params)
  File "C:\Users\Roark\OneDrive\Documentos\SPP2\spp-django\venv\Lib\site-packages\django\db\backends\utils.py", line 102, in execute
    return super().execute(sql, params)
           ^^^^^^^^^^^^^^^^^^^^^^^^^^^^
  File "C:\Users\Roark\OneDrive\Documentos\SPP2\spp-django\venv\Lib\site-packages\django\db\backends\utils.py", line 67, in execute
    return self._execute_with_wrappers(
           ^^^^^^^^^^^^^^^^^^^^^^^^^^^^
  File "C:\Users\Roark\OneDrive\Documentos\SPP2\spp-django\venv\Lib\site-packages\django\db\backends\utils.py", line 80, in _execute_with_wrappers
    return executor(sql, params, many, context)
           ^^^^^^^^^^^^^^^^^^^^^^^^^^^^^^^^^^^^
  File "C:\Users\Roark\OneDrive\Documentos\SPP2\spp-django\venv\Lib\site-packages\django\db\backends\utils.py", line 84, in _execute
    with self.db.wrap_database_errors:
  File "C:\Users\Roark\OneDrive\Documentos\SPP2\spp-django\venv\Lib\site-packages\django\db\utils.py", line 91, in __exit__
    raise dj_exc_value.with_traceback(traceback) from exc_value
  File "C:\Users\Roark\OneDrive\Documentos\SPP2\spp-django\venv\Lib\site-packages\django\db\backends\utils.py", line 89, in _execute
    return self.cursor.execute(sql, params)
           ^^^^^^^^^^^^^^^^^^^^^^^^^^^^^^^^
  File "C:\Users\Roark\OneDrive\Documentos\SPP2\spp-django\venv\Lib\site-packages\mssql\base.py", line 621, in execute
    return self.cursor.execute(sql, params)
           ^^^^^^^^^^^^^^^^^^^^^^^^^^^^^^^^
django.db.utils.IntegrityError: ('23000', "[23000] [Microsoft][ODBC Driver 17 for SQL Server][SQL Server]Cannot insert the value NULL into column 'cliente', table 'SPPDB2.0.dbo.core_pedido'; column does not allow nulls. INSERT fails. (515) (SQLExecDirectW); [23000] [Microsoft][ODBC Driver 17 for SQL Server][SQL Server]The statement has been terminated. (3621)")
('23000', "[23000] [Microsoft][ODBC Driver 17 for SQL Server][SQL Server]Cannot insert the value NULL into column 'cliente', table 'SPPDB2.0.dbo.core_pedido'; column does not allow nulls. INSERT fails. (515) (SQLExecDirectW); [23000] [Microsoft][ODBC Driver 17 for SQL Server][SQL Server]The statement has been terminated. (3621)")
Traceback (most recent call last):
  File "C:\Users\Roark\OneDrive\Documentos\SPP2\spp-django\venv\Lib\site-packages\django\db\backends\utils.py", line 89, in _execute
    return self.cursor.execute(sql, params)
           ^^^^^^^^^^^^^^^^^^^^^^^^^^^^^^^^
  File "C:\Users\Roark\OneDrive\Documentos\SPP2\spp-django\venv\Lib\site-packages\mssql\base.py", line 621, in execute
    return self.cursor.execute(sql, params)
           ^^^^^^^^^^^^^^^^^^^^^^^^^^^^^^^^
pyodbc.IntegrityError: ('23000', "[23000] [Microsoft][ODBC Driver 17 for SQL Server][SQL Server]Cannot insert the value NULL into column 'cliente', table 'SPPDB2.0.dbo.core_pedido'; column does not allow nulls. INSERT fails. (515) (SQLExecDirectW); [23000] [Microsoft][ODBC Driver 17 for SQL Server][SQL Server]The statement has been terminated. (3621)")

The above exception was the direct cause of the following exception:

Traceback (most recent call last):
  File "C:\Users\Roark\OneDrive\Documentos\SPP2\spp-django\venv\Lib\site-packages\import_export\resources.py", line 748, in import_row
    self.save_instance(instance, new, using_transactions, dry_run)
  File "C:\Users\Roark\OneDrive\Documentos\SPP2\spp-django\venv\Lib\site-packages\import_export\resources.py", line 491, in save_instance
    instance.save()
  File "C:\Users\Roark\OneDrive\Documentos\SPP2\spp-django\venv\Lib\site-packages\django\db\models\base.py", line 814, in save
    self.save_base(
  File "C:\Users\Roark\OneDrive\Documentos\SPP2\spp-django\venv\Lib\site-packages\django\db\models\base.py", line 877, in save_base
    updated = self._save_table(
              ^^^^^^^^^^^^^^^^^
  File "C:\Users\Roark\OneDrive\Documentos\SPP2\spp-django\venv\Lib\site-packages\django\db\models\base.py", line 1020, in _save_table
    results = self._do_insert(
              ^^^^^^^^^^^^^^^^
  File "C:\Users\Roark\OneDrive\Documentos\SPP2\spp-django\venv\Lib\site-packages\django\db\models\base.py", line 1061, in _do_insert
    return manager._insert(
           ^^^^^^^^^^^^^^^^
  File "C:\Users\Roark\OneDrive\Documentos\SPP2\spp-django\venv\Lib\site-packages\django\db\models\manager.py", line 87, in manager_method
    return getattr(self.get_queryset(), name)(*args, **kwargs)
           ^^^^^^^^^^^^^^^^^^^^^^^^^^^^^^^^^^^^^^^^^^^^^^^^^^^
  File "C:\Users\Roark\OneDrive\Documentos\SPP2\spp-django\venv\Lib\site-packages\django\db\models\query.py", line 1805, in _insert
    return query.get_compiler(using=using).execute_sql(returning_fields)
           ^^^^^^^^^^^^^^^^^^^^^^^^^^^^^^^^^^^^^^^^^^^^^^^^^^^^^^^^^^^^^
  File "C:\Users\Roark\OneDrive\Documentos\SPP2\spp-django\venv\Lib\site-packages\django\db\models\sql\compiler.py", line 1822, in execute_sql
    cursor.execute(sql, params)
  File "C:\Users\Roark\OneDrive\Documentos\SPP2\spp-django\venv\Lib\site-packages\django\db\backends\utils.py", line 102, in execute
    return super().execute(sql, params)
           ^^^^^^^^^^^^^^^^^^^^^^^^^^^^
  File "C:\Users\Roark\OneDrive\Documentos\SPP2\spp-django\venv\Lib\site-packages\django\db\backends\utils.py", line 67, in execute
    return self._execute_with_wrappers(
           ^^^^^^^^^^^^^^^^^^^^^^^^^^^^
  File "C:\Users\Roark\OneDrive\Documentos\SPP2\spp-django\venv\Lib\site-packages\django\db\backends\utils.py", line 80, in _execute_with_wrappers
    return executor(sql, params, many, context)
           ^^^^^^^^^^^^^^^^^^^^^^^^^^^^^^^^^^^^
  File "C:\Users\Roark\OneDrive\Documentos\SPP2\spp-django\venv\Lib\site-packages\django\db\backends\utils.py", line 84, in _execute
    with self.db.wrap_database_errors:
  File "C:\Users\Roark\OneDrive\Documentos\SPP2\spp-django\venv\Lib\site-packages\django\db\utils.py", line 91, in __exit__
    raise dj_exc_value.with_traceback(traceback) from exc_value
  File "C:\Users\Roark\OneDrive\Documentos\SPP2\spp-django\venv\Lib\site-packages\django\db\backends\utils.py", line 89, in _execute
    return self.cursor.execute(sql, params)
           ^^^^^^^^^^^^^^^^^^^^^^^^^^^^^^^^
  File "C:\Users\Roark\OneDrive\Documentos\SPP2\spp-django\venv\Lib\site-packages\mssql\base.py", line 621, in execute
    return self.cursor.execute(sql, params)
           ^^^^^^^^^^^^^^^^^^^^^^^^^^^^^^^^
django.db.utils.IntegrityError: ('23000', "[23000] [Microsoft][ODBC Driver 17 for SQL Server][SQL Server]Cannot insert the value NULL into column 'cliente', table 'SPPDB2.0.dbo.core_pedido'; column does not allow nulls. INSERT fails. (515) (SQLExecDirectW); [23000] [Microsoft][ODBC Driver 17 for SQL Server][SQL Server]The statement has been terminated. (3621)")
('23000', "[23000] [Microsoft][ODBC Driver 17 for SQL Server][SQL Server]Cannot insert the value NULL into column 'cliente', table 'SPPDB2.0.dbo.core_pedido'; column does not allow nulls. INSERT fails. (515) (SQLExecDirectW); [23000] [Microsoft][ODBC Driver 17 for SQL Server][SQL Server]The statement has been terminated. (3621)")
Traceback (most recent call last):
  File "C:\Users\Roark\OneDrive\Documentos\SPP2\spp-django\venv\Lib\site-packages\django\db\backends\utils.py", line 89, in _execute
    return self.cursor.execute(sql, params)
           ^^^^^^^^^^^^^^^^^^^^^^^^^^^^^^^^
  File "C:\Users\Roark\OneDrive\Documentos\SPP2\spp-django\venv\Lib\site-packages\mssql\base.py", line 621, in execute
    return self.cursor.execute(sql, params)
           ^^^^^^^^^^^^^^^^^^^^^^^^^^^^^^^^
pyodbc.IntegrityError: ('23000', "[23000] [Microsoft][ODBC Driver 17 for SQL Server][SQL Server]Cannot insert the value NULL into column 'cliente', table 'SPPDB2.0.dbo.core_pedido'; column does not allow nulls. INSERT fails. (515) (SQLExecDirectW); [23000] [Microsoft][ODBC Driver 17 for SQL Server][SQL Server]The statement has been terminated. (3621)")

The above exception was the direct cause of the following exception:

Traceback (most recent call last):
  File "C:\Users\Roark\OneDrive\Documentos\SPP2\spp-django\venv\Lib\site-packages\import_export\resources.py", line 748, in import_row
    self.save_instance(instance, new, using_transactions, dry_run)
  File "C:\Users\Roark\OneDrive\Documentos\SPP2\spp-django\venv\Lib\site-packages\import_export\resources.py", line 491, in save_instance
    instance.save()
  File "C:\Users\Roark\OneDrive\Documentos\SPP2\spp-django\venv\Lib\site-packages\django\db\models\base.py", line 814, in save
    self.save_base(
  File "C:\Users\Roark\OneDrive\Documentos\SPP2\spp-django\venv\Lib\site-packages\django\db\models\base.py", line 877, in save_base
    updated = self._save_table(
              ^^^^^^^^^^^^^^^^^
  File "C:\Users\Roark\OneDrive\Documentos\SPP2\spp-django\venv\Lib\site-packages\django\db\models\base.py", line 1020, in _save_table
    results = self._do_insert(
              ^^^^^^^^^^^^^^^^
  File "C:\Users\Roark\OneDrive\Documentos\SPP2\spp-django\venv\Lib\site-packages\django\db\models\base.py", line 1061, in _do_insert
    return manager._insert(
           ^^^^^^^^^^^^^^^^
  File "C:\Users\Roark\OneDrive\Documentos\SPP2\spp-django\venv\Lib\site-packages\django\db\models\manager.py", line 87, in manager_method
    return getattr(self.get_queryset(), name)(*args, **kwargs)
           ^^^^^^^^^^^^^^^^^^^^^^^^^^^^^^^^^^^^^^^^^^^^^^^^^^^
  File "C:\Users\Roark\OneDrive\Documentos\SPP2\spp-django\venv\Lib\site-packages\django\db\models\query.py", line 1805, in _insert
    return query.get_compiler(using=using).execute_sql(returning_fields)
           ^^^^^^^^^^^^^^^^^^^^^^^^^^^^^^^^^^^^^^^^^^^^^^^^^^^^^^^^^^^^^
  File "C:\Users\Roark\OneDrive\Documentos\SPP2\spp-django\venv\Lib\site-packages\django\db\models\sql\compiler.py", line 1822, in execute_sql
    cursor.execute(sql, params)
  File "C:\Users\Roark\OneDrive\Documentos\SPP2\spp-django\venv\Lib\site-packages\django\db\backends\utils.py", line 102, in execute
    return super().execute(sql, params)
           ^^^^^^^^^^^^^^^^^^^^^^^^^^^^
  File "C:\Users\Roark\OneDrive\Documentos\SPP2\spp-django\venv\Lib\site-packages\django\db\backends\utils.py", line 67, in execute
    return self._execute_with_wrappers(
           ^^^^^^^^^^^^^^^^^^^^^^^^^^^^
  File "C:\Users\Roark\OneDrive\Documentos\SPP2\spp-django\venv\Lib\site-packages\django\db\backends\utils.py", line 80, in _execute_with_wrappers
    return executor(sql, params, many, context)
           ^^^^^^^^^^^^^^^^^^^^^^^^^^^^^^^^^^^^
  File "C:\Users\Roark\OneDrive\Documentos\SPP2\spp-django\venv\Lib\site-packages\django\db\backends\utils.py", line 84, in _execute
    with self.db.wrap_database_errors:
  File "C:\Users\Roark\OneDrive\Documentos\SPP2\spp-django\venv\Lib\site-packages\django\db\utils.py", line 91, in __exit__
    raise dj_exc_value.with_traceback(traceback) from exc_value
  File "C:\Users\Roark\OneDrive\Documentos\SPP2\spp-django\venv\Lib\site-packages\django\db\backends\utils.py", line 89, in _execute
    return self.cursor.execute(sql, params)
           ^^^^^^^^^^^^^^^^^^^^^^^^^^^^^^^^
  File "C:\Users\Roark\OneDrive\Documentos\SPP2\spp-django\venv\Lib\site-packages\mssql\base.py", line 621, in execute
    return self.cursor.execute(sql, params)
           ^^^^^^^^^^^^^^^^^^^^^^^^^^^^^^^^
django.db.utils.IntegrityError: ('23000', "[23000] [Microsoft][ODBC Driver 17 for SQL Server][SQL Server]Cannot insert the value NULL into column 'cliente', table 'SPPDB2.0.dbo.core_pedido'; column does not allow nulls. INSERT fails. (515) (SQLExecDirectW); [23000] [Microsoft][ODBC Driver 17 for SQL Server][SQL Server]The statement has been terminated. (3621)")
('23000', "[23000] [Microsoft][ODBC Driver 17 for SQL Server][SQL Server]Cannot insert the value NULL into column 'cliente', table 'SPPDB2.0.dbo.core_pedido'; column does not allow nulls. INSERT fails. (515) (SQLExecDirectW); [23000] [Microsoft][ODBC Driver 17 for SQL Server][SQL Server]The statement has been terminated. (3621)")
Traceback (most recent call last):
  File "C:\Users\Roark\OneDrive\Documentos\SPP2\spp-django\venv\Lib\site-packages\django\db\backends\utils.py", line 89, in _execute
    return self.cursor.execute(sql, params)
           ^^^^^^^^^^^^^^^^^^^^^^^^^^^^^^^^
  File "C:\Users\Roark\OneDrive\Documentos\SPP2\spp-django\venv\Lib\site-packages\mssql\base.py", line 621, in execute
    return self.cursor.execute(sql, params)
           ^^^^^^^^^^^^^^^^^^^^^^^^^^^^^^^^
pyodbc.IntegrityError: ('23000', "[23000] [Microsoft][ODBC Driver 17 for SQL Server][SQL Server]Cannot insert the value NULL into column 'cliente', table 'SPPDB2.0.dbo.core_pedido'; column does not allow nulls. INSERT fails. (515) (SQLExecDirectW); [23000] [Microsoft][ODBC Driver 17 for SQL Server][SQL Server]The statement has been terminated. (3621)")

The above exception was the direct cause of the following exception:

Traceback (most recent call last):
  File "C:\Users\Roark\OneDrive\Documentos\SPP2\spp-django\venv\Lib\site-packages\import_export\resources.py", line 748, in import_row
    self.save_instance(instance, new, using_transactions, dry_run)
  File "C:\Users\Roark\OneDrive\Documentos\SPP2\spp-django\venv\Lib\site-packages\import_export\resources.py", line 491, in save_instance
    instance.save()
  File "C:\Users\Roark\OneDrive\Documentos\SPP2\spp-django\venv\Lib\site-packages\django\db\models\base.py", line 814, in save
    self.save_base(
  File "C:\Users\Roark\OneDrive\Documentos\SPP2\spp-django\venv\Lib\site-packages\django\db\models\base.py", line 877, in save_base
    updated = self._save_table(
              ^^^^^^^^^^^^^^^^^
  File "C:\Users\Roark\OneDrive\Documentos\SPP2\spp-django\venv\Lib\site-packages\django\db\models\base.py", line 1020, in _save_table
    results = self._do_insert(
              ^^^^^^^^^^^^^^^^
  File "C:\Users\Roark\OneDrive\Documentos\SPP2\spp-django\venv\Lib\site-packages\django\db\models\base.py", line 1061, in _do_insert
    return manager._insert(
           ^^^^^^^^^^^^^^^^
  File "C:\Users\Roark\OneDrive\Documentos\SPP2\spp-django\venv\Lib\site-packages\django\db\models\manager.py", line 87, in manager_method
    return getattr(self.get_queryset(), name)(*args, **kwargs)
           ^^^^^^^^^^^^^^^^^^^^^^^^^^^^^^^^^^^^^^^^^^^^^^^^^^^
  File "C:\Users\Roark\OneDrive\Documentos\SPP2\spp-django\venv\Lib\site-packages\django\db\models\query.py", line 1805, in _insert
    return query.get_compiler(using=using).execute_sql(returning_fields)
           ^^^^^^^^^^^^^^^^^^^^^^^^^^^^^^^^^^^^^^^^^^^^^^^^^^^^^^^^^^^^^
  File "C:\Users\Roark\OneDrive\Documentos\SPP2\spp-django\venv\Lib\site-packages\django\db\models\sql\compiler.py", line 1822, in execute_sql
    cursor.execute(sql, params)
  File "C:\Users\Roark\OneDrive\Documentos\SPP2\spp-django\venv\Lib\site-packages\django\db\backends\utils.py", line 102, in execute
    return super().execute(sql, params)
           ^^^^^^^^^^^^^^^^^^^^^^^^^^^^
  File "C:\Users\Roark\OneDrive\Documentos\SPP2\spp-django\venv\Lib\site-packages\django\db\backends\utils.py", line 67, in execute
    return self._execute_with_wrappers(
           ^^^^^^^^^^^^^^^^^^^^^^^^^^^^
  File "C:\Users\Roark\OneDrive\Documentos\SPP2\spp-django\venv\Lib\site-packages\django\db\backends\utils.py", line 80, in _execute_with_wrappers
    return executor(sql, params, many, context)
           ^^^^^^^^^^^^^^^^^^^^^^^^^^^^^^^^^^^^
  File "C:\Users\Roark\OneDrive\Documentos\SPP2\spp-django\venv\Lib\site-packages\django\db\backends\utils.py", line 84, in _execute
    with self.db.wrap_database_errors:
  File "C:\Users\Roark\OneDrive\Documentos\SPP2\spp-django\venv\Lib\site-packages\django\db\utils.py", line 91, in __exit__
    raise dj_exc_value.with_traceback(traceback) from exc_value
  File "C:\Users\Roark\OneDrive\Documentos\SPP2\spp-django\venv\Lib\site-packages\django\db\backends\utils.py", line 89, in _execute
    return self.cursor.execute(sql, params)
           ^^^^^^^^^^^^^^^^^^^^^^^^^^^^^^^^
  File "C:\Users\Roark\OneDrive\Documentos\SPP2\spp-django\venv\Lib\site-packages\mssql\base.py", line 621, in execute
    return self.cursor.execute(sql, params)
           ^^^^^^^^^^^^^^^^^^^^^^^^^^^^^^^^
django.db.utils.IntegrityError: ('23000', "[23000] [Microsoft][ODBC Driver 17 for SQL Server][SQL Server]Cannot insert the value NULL into column 'cliente', table 'SPPDB2.0.dbo.core_pedido'; column does not allow nulls. INSERT fails. (515) (SQLExecDirectW); [23000] [Microsoft][ODBC Driver 17 for SQL Server][SQL Server]The statement has been terminated. (3621)")
('23000', "[23000] [Microsoft][ODBC Driver 17 for SQL Server][SQL Server]Cannot insert the value NULL into column 'cliente', table 'SPPDB2.0.dbo.core_pedido'; column does not allow nulls. INSERT fails. (515) (SQLExecDirectW); [23000] [Microsoft][ODBC Driver 17 for SQL Server][SQL Server]The statement has been terminated. (3621)")
Traceback (most recent call last):
  File "C:\Users\Roark\OneDrive\Documentos\SPP2\spp-django\venv\Lib\site-packages\django\db\backends\utils.py", line 89, in _execute
    return self.cursor.execute(sql, params)
           ^^^^^^^^^^^^^^^^^^^^^^^^^^^^^^^^
  File "C:\Users\Roark\OneDrive\Documentos\SPP2\spp-django\venv\Lib\site-packages\mssql\base.py", line 621, in execute
    return self.cursor.execute(sql, params)
           ^^^^^^^^^^^^^^^^^^^^^^^^^^^^^^^^
pyodbc.IntegrityError: ('23000', "[23000] [Microsoft][ODBC Driver 17 for SQL Server][SQL Server]Cannot insert the value NULL into column 'cliente', table 'SPPDB2.0.dbo.core_pedido'; column does not allow nulls. INSERT fails. (515) (SQLExecDirectW); [23000] [Microsoft][ODBC Driver 17 for SQL Server][SQL Server]The statement has been terminated. (3621)")

The above exception was the direct cause of the following exception:

Traceback (most recent call last):
  File "C:\Users\Roark\OneDrive\Documentos\SPP2\spp-django\venv\Lib\site-packages\import_export\resources.py", line 748, in import_row
    self.save_instance(instance, new, using_transactions, dry_run)
  File "C:\Users\Roark\OneDrive\Documentos\SPP2\spp-django\venv\Lib\site-packages\import_export\resources.py", line 491, in save_instance
    instance.save()
  File "C:\Users\Roark\OneDrive\Documentos\SPP2\spp-django\venv\Lib\site-packages\django\db\models\base.py", line 814, in save
    self.save_base(
  File "C:\Users\Roark\OneDrive\Documentos\SPP2\spp-django\venv\Lib\site-packages\django\db\models\base.py", line 877, in save_base
    updated = self._save_table(
              ^^^^^^^^^^^^^^^^^
  File "C:\Users\Roark\OneDrive\Documentos\SPP2\spp-django\venv\Lib\site-packages\django\db\models\base.py", line 1020, in _save_table
    results = self._do_insert(
              ^^^^^^^^^^^^^^^^
  File "C:\Users\Roark\OneDrive\Documentos\SPP2\spp-django\venv\Lib\site-packages\django\db\models\base.py", line 1061, in _do_insert
    return manager._insert(
           ^^^^^^^^^^^^^^^^
  File "C:\Users\Roark\OneDrive\Documentos\SPP2\spp-django\venv\Lib\site-packages\django\db\models\manager.py", line 87, in manager_method
    return getattr(self.get_queryset(), name)(*args, **kwargs)
           ^^^^^^^^^^^^^^^^^^^^^^^^^^^^^^^^^^^^^^^^^^^^^^^^^^^
  File "C:\Users\Roark\OneDrive\Documentos\SPP2\spp-django\venv\Lib\site-packages\django\db\models\query.py", line 1805, in _insert
    return query.get_compiler(using=using).execute_sql(returning_fields)
           ^^^^^^^^^^^^^^^^^^^^^^^^^^^^^^^^^^^^^^^^^^^^^^^^^^^^^^^^^^^^^
  File "C:\Users\Roark\OneDrive\Documentos\SPP2\spp-django\venv\Lib\site-packages\django\db\models\sql\compiler.py", line 1822, in execute_sql
    cursor.execute(sql, params)
  File "C:\Users\Roark\OneDrive\Documentos\SPP2\spp-django\venv\Lib\site-packages\django\db\backends\utils.py", line 102, in execute
    return super().execute(sql, params)
           ^^^^^^^^^^^^^^^^^^^^^^^^^^^^
  File "C:\Users\Roark\OneDrive\Documentos\SPP2\spp-django\venv\Lib\site-packages\django\db\backends\utils.py", line 67, in execute
    return self._execute_with_wrappers(
           ^^^^^^^^^^^^^^^^^^^^^^^^^^^^
  File "C:\Users\Roark\OneDrive\Documentos\SPP2\spp-django\venv\Lib\site-packages\django\db\backends\utils.py", line 80, in _execute_with_wrappers
    return executor(sql, params, many, context)
           ^^^^^^^^^^^^^^^^^^^^^^^^^^^^^^^^^^^^
  File "C:\Users\Roark\OneDrive\Documentos\SPP2\spp-django\venv\Lib\site-packages\django\db\backends\utils.py", line 84, in _execute
    with self.db.wrap_database_errors:
  File "C:\Users\Roark\OneDrive\Documentos\SPP2\spp-django\venv\Lib\site-packages\django\db\utils.py", line 91, in __exit__
    raise dj_exc_value.with_traceback(traceback) from exc_value
  File "C:\Users\Roark\OneDrive\Documentos\SPP2\spp-django\venv\Lib\site-packages\django\db\backends\utils.py", line 89, in _execute
    return self.cursor.execute(sql, params)
           ^^^^^^^^^^^^^^^^^^^^^^^^^^^^^^^^
  File "C:\Users\Roark\OneDrive\Documentos\SPP2\spp-django\venv\Lib\site-packages\mssql\base.py", line 621, in execute
    return self.cursor.execute(sql, params)
           ^^^^^^^^^^^^^^^^^^^^^^^^^^^^^^^^
django.db.utils.IntegrityError: ('23000', "[23000] [Microsoft][ODBC Driver 17 for SQL Server][SQL Server]Cannot insert the value NULL into column 'cliente', table 'SPPDB2.0.dbo.core_pedido'; column does not allow nulls. INSERT fails. (515) (SQLExecDirectW); [23000] [Microsoft][ODBC Driver 17 for SQL Server][SQL Server]The statement has been terminated. (3621)")
Internal Server Error: /importar/
Traceback (most recent call last):
  File "C:\Users\Roark\OneDrive\Documentos\SPP2\spp-django\venv\Lib\site-packages\django\core\handlers\exception.py", line 55, in inner
    response = get_response(request)
               ^^^^^^^^^^^^^^^^^^^^^
  File "C:\Users\Roark\OneDrive\Documentos\SPP2\spp-django\venv\Lib\site-packages\django\core\handlers\base.py", line 197, in _get_response
    response = wrapped_callback(request, *callback_args, **callback_kwargs)
               ^^^^^^^^^^^^^^^^^^^^^^^^^^^^^^^^^^^^^^^^^^^^^^^^^^^^^^^^^^^^
  File "C:\Users\Roark\OneDrive\Documentos\SPP2\spp-django\core\views.py", line 83, in importar
    logger.error("Data import failed. Please check the file format.")
    ^^^^^^
NameError: name 'logger' is not defined
Not Found: /favicon.ico
C:\Users\Roark\OneDrive\Documentos\SPP2\SPP-Django\core\views.py changed, reloading.
AXES: BEGIN version 6.1.0, blocking by ip_address
Watching for file changes with StatReloader
Unable to import numpy
Traceback (most recent call last):
  File "C:\Users\Roark\OneDrive\Documentos\SPP2\spp-django\venv\Lib\site-packages\mip\ndarray.py", line 6, in <module>
    import numpy as np
ModuleNotFoundError: No module named 'numpy'
Numpy not available
Traceback (most recent call last):
  File "C:\Users\Roark\OneDrive\Documentos\SPP2\spp-django\venv\Lib\site-packages\mip\model.py", line 12, in <module>
    import numpy as np
ModuleNotFoundError: No module named 'numpy'
Using Python-MIP package version 1.15.0
C:\Users\Roark\OneDrive\Documentos\SPP2\SPP-Django\core\views.py changed, reloading.
AXES: BEGIN version 6.1.0, blocking by ip_address
Watching for file changes with StatReloader
Unable to import numpy
Traceback (most recent call last):
  File "C:\Users\Roark\OneDrive\Documentos\SPP2\spp-django\venv\Lib\site-packages\mip\ndarray.py", line 6, in <module>
    import numpy as np
ModuleNotFoundError: No module named 'numpy'
Numpy not available
Traceback (most recent call last):
  File "C:\Users\Roark\OneDrive\Documentos\SPP2\spp-django\venv\Lib\site-packages\mip\model.py", line 12, in <module>
    import numpy as np
ModuleNotFoundError: No module named 'numpy'
Using Python-MIP package version 1.15.0
('23000', "[23000] [Microsoft][ODBC Driver 17 for SQL Server][SQL Server]Cannot insert the value NULL into column 'cliente', table 'SPPDB2.0.dbo.core_pedido'; column does not allow nulls. INSERT fails. (515) (SQLExecDirectW); [23000] [Microsoft][ODBC Driver 17 for SQL Server][SQL Server]The statement has been terminated. (3621)")
Traceback (most recent call last):
  File "C:\Users\Roark\OneDrive\Documentos\SPP2\spp-django\venv\Lib\site-packages\django\db\backends\utils.py", line 89, in _execute
    return self.cursor.execute(sql, params)
           ^^^^^^^^^^^^^^^^^^^^^^^^^^^^^^^^
  File "C:\Users\Roark\OneDrive\Documentos\SPP2\spp-django\venv\Lib\site-packages\mssql\base.py", line 621, in execute
    return self.cursor.execute(sql, params)
           ^^^^^^^^^^^^^^^^^^^^^^^^^^^^^^^^
pyodbc.IntegrityError: ('23000', "[23000] [Microsoft][ODBC Driver 17 for SQL Server][SQL Server]Cannot insert the value NULL into column 'cliente', table 'SPPDB2.0.dbo.core_pedido'; column does not allow nulls. INSERT fails. (515) (SQLExecDirectW); [23000] [Microsoft][ODBC Driver 17 for SQL Server][SQL Server]The statement has been terminated. (3621)")

The above exception was the direct cause of the following exception:

Traceback (most recent call last):
  File "C:\Users\Roark\OneDrive\Documentos\SPP2\spp-django\venv\Lib\site-packages\import_export\resources.py", line 748, in import_row
    self.save_instance(instance, new, using_transactions, dry_run)
  File "C:\Users\Roark\OneDrive\Documentos\SPP2\spp-django\venv\Lib\site-packages\import_export\resources.py", line 491, in save_instance
    instance.save()
  File "C:\Users\Roark\OneDrive\Documentos\SPP2\spp-django\venv\Lib\site-packages\django\db\models\base.py", line 814, in save
    self.save_base(
  File "C:\Users\Roark\OneDrive\Documentos\SPP2\spp-django\venv\Lib\site-packages\django\db\models\base.py", line 877, in save_base
    updated = self._save_table(
              ^^^^^^^^^^^^^^^^^
  File "C:\Users\Roark\OneDrive\Documentos\SPP2\spp-django\venv\Lib\site-packages\django\db\models\base.py", line 1020, in _save_table
    results = self._do_insert(
              ^^^^^^^^^^^^^^^^
  File "C:\Users\Roark\OneDrive\Documentos\SPP2\spp-django\venv\Lib\site-packages\django\db\models\base.py", line 1061, in _do_insert
    return manager._insert(
           ^^^^^^^^^^^^^^^^
  File "C:\Users\Roark\OneDrive\Documentos\SPP2\spp-django\venv\Lib\site-packages\django\db\models\manager.py", line 87, in manager_method
    return getattr(self.get_queryset(), name)(*args, **kwargs)
           ^^^^^^^^^^^^^^^^^^^^^^^^^^^^^^^^^^^^^^^^^^^^^^^^^^^
  File "C:\Users\Roark\OneDrive\Documentos\SPP2\spp-django\venv\Lib\site-packages\django\db\models\query.py", line 1805, in _insert
    return query.get_compiler(using=using).execute_sql(returning_fields)
           ^^^^^^^^^^^^^^^^^^^^^^^^^^^^^^^^^^^^^^^^^^^^^^^^^^^^^^^^^^^^^
  File "C:\Users\Roark\OneDrive\Documentos\SPP2\spp-django\venv\Lib\site-packages\django\db\models\sql\compiler.py", line 1822, in execute_sql
    cursor.execute(sql, params)
  File "C:\Users\Roark\OneDrive\Documentos\SPP2\spp-django\venv\Lib\site-packages\django\db\backends\utils.py", line 102, in execute
    return super().execute(sql, params)
           ^^^^^^^^^^^^^^^^^^^^^^^^^^^^
  File "C:\Users\Roark\OneDrive\Documentos\SPP2\spp-django\venv\Lib\site-packages\django\db\backends\utils.py", line 67, in execute
    return self._execute_with_wrappers(
           ^^^^^^^^^^^^^^^^^^^^^^^^^^^^
  File "C:\Users\Roark\OneDrive\Documentos\SPP2\spp-django\venv\Lib\site-packages\django\db\backends\utils.py", line 80, in _execute_with_wrappers
    return executor(sql, params, many, context)
           ^^^^^^^^^^^^^^^^^^^^^^^^^^^^^^^^^^^^
  File "C:\Users\Roark\OneDrive\Documentos\SPP2\spp-django\venv\Lib\site-packages\django\db\backends\utils.py", line 84, in _execute
    with self.db.wrap_database_errors:
  File "C:\Users\Roark\OneDrive\Documentos\SPP2\spp-django\venv\Lib\site-packages\django\db\utils.py", line 91, in __exit__
    raise dj_exc_value.with_traceback(traceback) from exc_value
  File "C:\Users\Roark\OneDrive\Documentos\SPP2\spp-django\venv\Lib\site-packages\django\db\backends\utils.py", line 89, in _execute
    return self.cursor.execute(sql, params)
           ^^^^^^^^^^^^^^^^^^^^^^^^^^^^^^^^
  File "C:\Users\Roark\OneDrive\Documentos\SPP2\spp-django\venv\Lib\site-packages\mssql\base.py", line 621, in execute
    return self.cursor.execute(sql, params)
           ^^^^^^^^^^^^^^^^^^^^^^^^^^^^^^^^
django.db.utils.IntegrityError: ('23000', "[23000] [Microsoft][ODBC Driver 17 for SQL Server][SQL Server]Cannot insert the value NULL into column 'cliente', table 'SPPDB2.0.dbo.core_pedido'; column does not allow nulls. INSERT fails. (515) (SQLExecDirectW); [23000] [Microsoft][ODBC Driver 17 for SQL Server][SQL Server]The statement has been terminated. (3621)")
('23000', "[23000] [Microsoft][ODBC Driver 17 for SQL Server][SQL Server]Cannot insert the value NULL into column 'cliente', table 'SPPDB2.0.dbo.core_pedido'; column does not allow nulls. INSERT fails. (515) (SQLExecDirectW); [23000] [Microsoft][ODBC Driver 17 for SQL Server][SQL Server]The statement has been terminated. (3621)")
Traceback (most recent call last):
  File "C:\Users\Roark\OneDrive\Documentos\SPP2\spp-django\venv\Lib\site-packages\django\db\backends\utils.py", line 89, in _execute
    return self.cursor.execute(sql, params)
           ^^^^^^^^^^^^^^^^^^^^^^^^^^^^^^^^
  File "C:\Users\Roark\OneDrive\Documentos\SPP2\spp-django\venv\Lib\site-packages\mssql\base.py", line 621, in execute
    return self.cursor.execute(sql, params)
           ^^^^^^^^^^^^^^^^^^^^^^^^^^^^^^^^
pyodbc.IntegrityError: ('23000', "[23000] [Microsoft][ODBC Driver 17 for SQL Server][SQL Server]Cannot insert the value NULL into column 'cliente', table 'SPPDB2.0.dbo.core_pedido'; column does not allow nulls. INSERT fails. (515) (SQLExecDirectW); [23000] [Microsoft][ODBC Driver 17 for SQL Server][SQL Server]The statement has been terminated. (3621)")

The above exception was the direct cause of the following exception:

Traceback (most recent call last):
  File "C:\Users\Roark\OneDrive\Documentos\SPP2\spp-django\venv\Lib\site-packages\import_export\resources.py", line 748, in import_row
    self.save_instance(instance, new, using_transactions, dry_run)
  File "C:\Users\Roark\OneDrive\Documentos\SPP2\spp-django\venv\Lib\site-packages\import_export\resources.py", line 491, in save_instance
    instance.save()
  File "C:\Users\Roark\OneDrive\Documentos\SPP2\spp-django\venv\Lib\site-packages\django\db\models\base.py", line 814, in save
    self.save_base(
  File "C:\Users\Roark\OneDrive\Documentos\SPP2\spp-django\venv\Lib\site-packages\django\db\models\base.py", line 877, in save_base
    updated = self._save_table(
              ^^^^^^^^^^^^^^^^^
  File "C:\Users\Roark\OneDrive\Documentos\SPP2\spp-django\venv\Lib\site-packages\django\db\models\base.py", line 1020, in _save_table
    results = self._do_insert(
              ^^^^^^^^^^^^^^^^
  File "C:\Users\Roark\OneDrive\Documentos\SPP2\spp-django\venv\Lib\site-packages\django\db\models\base.py", line 1061, in _do_insert
    return manager._insert(
           ^^^^^^^^^^^^^^^^
  File "C:\Users\Roark\OneDrive\Documentos\SPP2\spp-django\venv\Lib\site-packages\django\db\models\manager.py", line 87, in manager_method
    return getattr(self.get_queryset(), name)(*args, **kwargs)
           ^^^^^^^^^^^^^^^^^^^^^^^^^^^^^^^^^^^^^^^^^^^^^^^^^^^
  File "C:\Users\Roark\OneDrive\Documentos\SPP2\spp-django\venv\Lib\site-packages\django\db\models\query.py", line 1805, in _insert
    return query.get_compiler(using=using).execute_sql(returning_fields)
           ^^^^^^^^^^^^^^^^^^^^^^^^^^^^^^^^^^^^^^^^^^^^^^^^^^^^^^^^^^^^^
  File "C:\Users\Roark\OneDrive\Documentos\SPP2\spp-django\venv\Lib\site-packages\django\db\models\sql\compiler.py", line 1822, in execute_sql
    cursor.execute(sql, params)
  File "C:\Users\Roark\OneDrive\Documentos\SPP2\spp-django\venv\Lib\site-packages\django\db\backends\utils.py", line 102, in execute
    return super().execute(sql, params)
           ^^^^^^^^^^^^^^^^^^^^^^^^^^^^
  File "C:\Users\Roark\OneDrive\Documentos\SPP2\spp-django\venv\Lib\site-packages\django\db\backends\utils.py", line 67, in execute
    return self._execute_with_wrappers(
           ^^^^^^^^^^^^^^^^^^^^^^^^^^^^
  File "C:\Users\Roark\OneDrive\Documentos\SPP2\spp-django\venv\Lib\site-packages\django\db\backends\utils.py", line 80, in _execute_with_wrappers
    return executor(sql, params, many, context)
           ^^^^^^^^^^^^^^^^^^^^^^^^^^^^^^^^^^^^
  File "C:\Users\Roark\OneDrive\Documentos\SPP2\spp-django\venv\Lib\site-packages\django\db\backends\utils.py", line 84, in _execute
    with self.db.wrap_database_errors:
  File "C:\Users\Roark\OneDrive\Documentos\SPP2\spp-django\venv\Lib\site-packages\django\db\utils.py", line 91, in __exit__
    raise dj_exc_value.with_traceback(traceback) from exc_value
  File "C:\Users\Roark\OneDrive\Documentos\SPP2\spp-django\venv\Lib\site-packages\django\db\backends\utils.py", line 89, in _execute
    return self.cursor.execute(sql, params)
           ^^^^^^^^^^^^^^^^^^^^^^^^^^^^^^^^
  File "C:\Users\Roark\OneDrive\Documentos\SPP2\spp-django\venv\Lib\site-packages\mssql\base.py", line 621, in execute
    return self.cursor.execute(sql, params)
           ^^^^^^^^^^^^^^^^^^^^^^^^^^^^^^^^
django.db.utils.IntegrityError: ('23000', "[23000] [Microsoft][ODBC Driver 17 for SQL Server][SQL Server]Cannot insert the value NULL into column 'cliente', table 'SPPDB2.0.dbo.core_pedido'; column does not allow nulls. INSERT fails. (515) (SQLExecDirectW); [23000] [Microsoft][ODBC Driver 17 for SQL Server][SQL Server]The statement has been terminated. (3621)")
('23000', "[23000] [Microsoft][ODBC Driver 17 for SQL Server][SQL Server]Cannot insert the value NULL into column 'cliente', table 'SPPDB2.0.dbo.core_pedido'; column does not allow nulls. INSERT fails. (515) (SQLExecDirectW); [23000] [Microsoft][ODBC Driver 17 for SQL Server][SQL Server]The statement has been terminated. (3621)")
Traceback (most recent call last):
  File "C:\Users\Roark\OneDrive\Documentos\SPP2\spp-django\venv\Lib\site-packages\django\db\backends\utils.py", line 89, in _execute
    return self.cursor.execute(sql, params)
           ^^^^^^^^^^^^^^^^^^^^^^^^^^^^^^^^
  File "C:\Users\Roark\OneDrive\Documentos\SPP2\spp-django\venv\Lib\site-packages\mssql\base.py", line 621, in execute
    return self.cursor.execute(sql, params)
           ^^^^^^^^^^^^^^^^^^^^^^^^^^^^^^^^
pyodbc.IntegrityError: ('23000', "[23000] [Microsoft][ODBC Driver 17 for SQL Server][SQL Server]Cannot insert the value NULL into column 'cliente', table 'SPPDB2.0.dbo.core_pedido'; column does not allow nulls. INSERT fails. (515) (SQLExecDirectW); [23000] [Microsoft][ODBC Driver 17 for SQL Server][SQL Server]The statement has been terminated. (3621)")

The above exception was the direct cause of the following exception:

Traceback (most recent call last):
  File "C:\Users\Roark\OneDrive\Documentos\SPP2\spp-django\venv\Lib\site-packages\import_export\resources.py", line 748, in import_row
    self.save_instance(instance, new, using_transactions, dry_run)
  File "C:\Users\Roark\OneDrive\Documentos\SPP2\spp-django\venv\Lib\site-packages\import_export\resources.py", line 491, in save_instance
    instance.save()
  File "C:\Users\Roark\OneDrive\Documentos\SPP2\spp-django\venv\Lib\site-packages\django\db\models\base.py", line 814, in save
    self.save_base(
  File "C:\Users\Roark\OneDrive\Documentos\SPP2\spp-django\venv\Lib\site-packages\django\db\models\base.py", line 877, in save_base
    updated = self._save_table(
              ^^^^^^^^^^^^^^^^^
  File "C:\Users\Roark\OneDrive\Documentos\SPP2\spp-django\venv\Lib\site-packages\django\db\models\base.py", line 1020, in _save_table
    results = self._do_insert(
              ^^^^^^^^^^^^^^^^
  File "C:\Users\Roark\OneDrive\Documentos\SPP2\spp-django\venv\Lib\site-packages\django\db\models\base.py", line 1061, in _do_insert
    return manager._insert(
           ^^^^^^^^^^^^^^^^
  File "C:\Users\Roark\OneDrive\Documentos\SPP2\spp-django\venv\Lib\site-packages\django\db\models\manager.py", line 87, in manager_method
    return getattr(self.get_queryset(), name)(*args, **kwargs)
           ^^^^^^^^^^^^^^^^^^^^^^^^^^^^^^^^^^^^^^^^^^^^^^^^^^^
  File "C:\Users\Roark\OneDrive\Documentos\SPP2\spp-django\venv\Lib\site-packages\django\db\models\query.py", line 1805, in _insert
    return query.get_compiler(using=using).execute_sql(returning_fields)
           ^^^^^^^^^^^^^^^^^^^^^^^^^^^^^^^^^^^^^^^^^^^^^^^^^^^^^^^^^^^^^
  File "C:\Users\Roark\OneDrive\Documentos\SPP2\spp-django\venv\Lib\site-packages\django\db\models\sql\compiler.py", line 1822, in execute_sql
    cursor.execute(sql, params)
  File "C:\Users\Roark\OneDrive\Documentos\SPP2\spp-django\venv\Lib\site-packages\django\db\backends\utils.py", line 102, in execute
    return super().execute(sql, params)
           ^^^^^^^^^^^^^^^^^^^^^^^^^^^^
  File "C:\Users\Roark\OneDrive\Documentos\SPP2\spp-django\venv\Lib\site-packages\django\db\backends\utils.py", line 67, in execute
    return self._execute_with_wrappers(
           ^^^^^^^^^^^^^^^^^^^^^^^^^^^^
  File "C:\Users\Roark\OneDrive\Documentos\SPP2\spp-django\venv\Lib\site-packages\django\db\backends\utils.py", line 80, in _execute_with_wrappers
    return executor(sql, params, many, context)
           ^^^^^^^^^^^^^^^^^^^^^^^^^^^^^^^^^^^^
  File "C:\Users\Roark\OneDrive\Documentos\SPP2\spp-django\venv\Lib\site-packages\django\db\backends\utils.py", line 84, in _execute
    with self.db.wrap_database_errors:
  File "C:\Users\Roark\OneDrive\Documentos\SPP2\spp-django\venv\Lib\site-packages\django\db\utils.py", line 91, in __exit__
    raise dj_exc_value.with_traceback(traceback) from exc_value
  File "C:\Users\Roark\OneDrive\Documentos\SPP2\spp-django\venv\Lib\site-packages\django\db\backends\utils.py", line 89, in _execute
    return self.cursor.execute(sql, params)
           ^^^^^^^^^^^^^^^^^^^^^^^^^^^^^^^^
  File "C:\Users\Roark\OneDrive\Documentos\SPP2\spp-django\venv\Lib\site-packages\mssql\base.py", line 621, in execute
    return self.cursor.execute(sql, params)
           ^^^^^^^^^^^^^^^^^^^^^^^^^^^^^^^^
django.db.utils.IntegrityError: ('23000', "[23000] [Microsoft][ODBC Driver 17 for SQL Server][SQL Server]Cannot insert the value NULL into column 'cliente', table 'SPPDB2.0.dbo.core_pedido'; column does not allow nulls. INSERT fails. (515) (SQLExecDirectW); [23000] [Microsoft][ODBC Driver 17 for SQL Server][SQL Server]The statement has been terminated. (3621)")
('23000', "[23000] [Microsoft][ODBC Driver 17 for SQL Server][SQL Server]Cannot insert the value NULL into column 'cliente', table 'SPPDB2.0.dbo.core_pedido'; column does not allow nulls. INSERT fails. (515) (SQLExecDirectW); [23000] [Microsoft][ODBC Driver 17 for SQL Server][SQL Server]The statement has been terminated. (3621)")
Traceback (most recent call last):
  File "C:\Users\Roark\OneDrive\Documentos\SPP2\spp-django\venv\Lib\site-packages\django\db\backends\utils.py", line 89, in _execute
    return self.cursor.execute(sql, params)
           ^^^^^^^^^^^^^^^^^^^^^^^^^^^^^^^^
  File "C:\Users\Roark\OneDrive\Documentos\SPP2\spp-django\venv\Lib\site-packages\mssql\base.py", line 621, in execute
    return self.cursor.execute(sql, params)
           ^^^^^^^^^^^^^^^^^^^^^^^^^^^^^^^^
pyodbc.IntegrityError: ('23000', "[23000] [Microsoft][ODBC Driver 17 for SQL Server][SQL Server]Cannot insert the value NULL into column 'cliente', table 'SPPDB2.0.dbo.core_pedido'; column does not allow nulls. INSERT fails. (515) (SQLExecDirectW); [23000] [Microsoft][ODBC Driver 17 for SQL Server][SQL Server]The statement has been terminated. (3621)")

The above exception was the direct cause of the following exception:

Traceback (most recent call last):
  File "C:\Users\Roark\OneDrive\Documentos\SPP2\spp-django\venv\Lib\site-packages\import_export\resources.py", line 748, in import_row
    self.save_instance(instance, new, using_transactions, dry_run)
  File "C:\Users\Roark\OneDrive\Documentos\SPP2\spp-django\venv\Lib\site-packages\import_export\resources.py", line 491, in save_instance
    instance.save()
  File "C:\Users\Roark\OneDrive\Documentos\SPP2\spp-django\venv\Lib\site-packages\django\db\models\base.py", line 814, in save
    self.save_base(
  File "C:\Users\Roark\OneDrive\Documentos\SPP2\spp-django\venv\Lib\site-packages\django\db\models\base.py", line 877, in save_base
    updated = self._save_table(
              ^^^^^^^^^^^^^^^^^
  File "C:\Users\Roark\OneDrive\Documentos\SPP2\spp-django\venv\Lib\site-packages\django\db\models\base.py", line 1020, in _save_table
    results = self._do_insert(
              ^^^^^^^^^^^^^^^^
  File "C:\Users\Roark\OneDrive\Documentos\SPP2\spp-django\venv\Lib\site-packages\django\db\models\base.py", line 1061, in _do_insert
    return manager._insert(
           ^^^^^^^^^^^^^^^^
  File "C:\Users\Roark\OneDrive\Documentos\SPP2\spp-django\venv\Lib\site-packages\django\db\models\manager.py", line 87, in manager_method
    return getattr(self.get_queryset(), name)(*args, **kwargs)
           ^^^^^^^^^^^^^^^^^^^^^^^^^^^^^^^^^^^^^^^^^^^^^^^^^^^
  File "C:\Users\Roark\OneDrive\Documentos\SPP2\spp-django\venv\Lib\site-packages\django\db\models\query.py", line 1805, in _insert
    return query.get_compiler(using=using).execute_sql(returning_fields)
           ^^^^^^^^^^^^^^^^^^^^^^^^^^^^^^^^^^^^^^^^^^^^^^^^^^^^^^^^^^^^^
  File "C:\Users\Roark\OneDrive\Documentos\SPP2\spp-django\venv\Lib\site-packages\django\db\models\sql\compiler.py", line 1822, in execute_sql
    cursor.execute(sql, params)
  File "C:\Users\Roark\OneDrive\Documentos\SPP2\spp-django\venv\Lib\site-packages\django\db\backends\utils.py", line 102, in execute
    return super().execute(sql, params)
           ^^^^^^^^^^^^^^^^^^^^^^^^^^^^
  File "C:\Users\Roark\OneDrive\Documentos\SPP2\spp-django\venv\Lib\site-packages\django\db\backends\utils.py", line 67, in execute
    return self._execute_with_wrappers(
           ^^^^^^^^^^^^^^^^^^^^^^^^^^^^
  File "C:\Users\Roark\OneDrive\Documentos\SPP2\spp-django\venv\Lib\site-packages\django\db\backends\utils.py", line 80, in _execute_with_wrappers
    return executor(sql, params, many, context)
           ^^^^^^^^^^^^^^^^^^^^^^^^^^^^^^^^^^^^
  File "C:\Users\Roark\OneDrive\Documentos\SPP2\spp-django\venv\Lib\site-packages\django\db\backends\utils.py", line 84, in _execute
    with self.db.wrap_database_errors:
  File "C:\Users\Roark\OneDrive\Documentos\SPP2\spp-django\venv\Lib\site-packages\django\db\utils.py", line 91, in __exit__
    raise dj_exc_value.with_traceback(traceback) from exc_value
  File "C:\Users\Roark\OneDrive\Documentos\SPP2\spp-django\venv\Lib\site-packages\django\db\backends\utils.py", line 89, in _execute
    return self.cursor.execute(sql, params)
           ^^^^^^^^^^^^^^^^^^^^^^^^^^^^^^^^
  File "C:\Users\Roark\OneDrive\Documentos\SPP2\spp-django\venv\Lib\site-packages\mssql\base.py", line 621, in execute
    return self.cursor.execute(sql, params)
           ^^^^^^^^^^^^^^^^^^^^^^^^^^^^^^^^
django.db.utils.IntegrityError: ('23000', "[23000] [Microsoft][ODBC Driver 17 for SQL Server][SQL Server]Cannot insert the value NULL into column 'cliente', table 'SPPDB2.0.dbo.core_pedido'; column does not allow nulls. INSERT fails. (515) (SQLExecDirectW); [23000] [Microsoft][ODBC Driver 17 for SQL Server][SQL Server]The statement has been terminated. (3621)")
('23000', "[23000] [Microsoft][ODBC Driver 17 for SQL Server][SQL Server]Cannot insert the value NULL into column 'cliente', table 'SPPDB2.0.dbo.core_pedido'; column does not allow nulls. INSERT fails. (515) (SQLExecDirectW); [23000] [Microsoft][ODBC Driver 17 for SQL Server][SQL Server]The statement has been terminated. (3621)")
Traceback (most recent call last):
  File "C:\Users\Roark\OneDrive\Documentos\SPP2\spp-django\venv\Lib\site-packages\django\db\backends\utils.py", line 89, in _execute
    return self.cursor.execute(sql, params)
           ^^^^^^^^^^^^^^^^^^^^^^^^^^^^^^^^
  File "C:\Users\Roark\OneDrive\Documentos\SPP2\spp-django\venv\Lib\site-packages\mssql\base.py", line 621, in execute
    return self.cursor.execute(sql, params)
           ^^^^^^^^^^^^^^^^^^^^^^^^^^^^^^^^
pyodbc.IntegrityError: ('23000', "[23000] [Microsoft][ODBC Driver 17 for SQL Server][SQL Server]Cannot insert the value NULL into column 'cliente', table 'SPPDB2.0.dbo.core_pedido'; column does not allow nulls. INSERT fails. (515) (SQLExecDirectW); [23000] [Microsoft][ODBC Driver 17 for SQL Server][SQL Server]The statement has been terminated. (3621)")

The above exception was the direct cause of the following exception:

Traceback (most recent call last):
  File "C:\Users\Roark\OneDrive\Documentos\SPP2\spp-django\venv\Lib\site-packages\import_export\resources.py", line 748, in import_row
    self.save_instance(instance, new, using_transactions, dry_run)
  File "C:\Users\Roark\OneDrive\Documentos\SPP2\spp-django\venv\Lib\site-packages\import_export\resources.py", line 491, in save_instance
    instance.save()
  File "C:\Users\Roark\OneDrive\Documentos\SPP2\spp-django\venv\Lib\site-packages\django\db\models\base.py", line 814, in save
    self.save_base(
  File "C:\Users\Roark\OneDrive\Documentos\SPP2\spp-django\venv\Lib\site-packages\django\db\models\base.py", line 877, in save_base
    updated = self._save_table(
              ^^^^^^^^^^^^^^^^^
  File "C:\Users\Roark\OneDrive\Documentos\SPP2\spp-django\venv\Lib\site-packages\django\db\models\base.py", line 1020, in _save_table
    results = self._do_insert(
              ^^^^^^^^^^^^^^^^
  File "C:\Users\Roark\OneDrive\Documentos\SPP2\spp-django\venv\Lib\site-packages\django\db\models\base.py", line 1061, in _do_insert
    return manager._insert(
           ^^^^^^^^^^^^^^^^
  File "C:\Users\Roark\OneDrive\Documentos\SPP2\spp-django\venv\Lib\site-packages\django\db\models\manager.py", line 87, in manager_method
    return getattr(self.get_queryset(), name)(*args, **kwargs)
           ^^^^^^^^^^^^^^^^^^^^^^^^^^^^^^^^^^^^^^^^^^^^^^^^^^^
  File "C:\Users\Roark\OneDrive\Documentos\SPP2\spp-django\venv\Lib\site-packages\django\db\models\query.py", line 1805, in _insert
    return query.get_compiler(using=using).execute_sql(returning_fields)
           ^^^^^^^^^^^^^^^^^^^^^^^^^^^^^^^^^^^^^^^^^^^^^^^^^^^^^^^^^^^^^
  File "C:\Users\Roark\OneDrive\Documentos\SPP2\spp-django\venv\Lib\site-packages\django\db\models\sql\compiler.py", line 1822, in execute_sql
    cursor.execute(sql, params)
  File "C:\Users\Roark\OneDrive\Documentos\SPP2\spp-django\venv\Lib\site-packages\django\db\backends\utils.py", line 102, in execute
    return super().execute(sql, params)
           ^^^^^^^^^^^^^^^^^^^^^^^^^^^^
  File "C:\Users\Roark\OneDrive\Documentos\SPP2\spp-django\venv\Lib\site-packages\django\db\backends\utils.py", line 67, in execute
    return self._execute_with_wrappers(
           ^^^^^^^^^^^^^^^^^^^^^^^^^^^^
  File "C:\Users\Roark\OneDrive\Documentos\SPP2\spp-django\venv\Lib\site-packages\django\db\backends\utils.py", line 80, in _execute_with_wrappers
    return executor(sql, params, many, context)
           ^^^^^^^^^^^^^^^^^^^^^^^^^^^^^^^^^^^^
  File "C:\Users\Roark\OneDrive\Documentos\SPP2\spp-django\venv\Lib\site-packages\django\db\backends\utils.py", line 84, in _execute
    with self.db.wrap_database_errors:
  File "C:\Users\Roark\OneDrive\Documentos\SPP2\spp-django\venv\Lib\site-packages\django\db\utils.py", line 91, in __exit__
    raise dj_exc_value.with_traceback(traceback) from exc_value
  File "C:\Users\Roark\OneDrive\Documentos\SPP2\spp-django\venv\Lib\site-packages\django\db\backends\utils.py", line 89, in _execute
    return self.cursor.execute(sql, params)
           ^^^^^^^^^^^^^^^^^^^^^^^^^^^^^^^^
  File "C:\Users\Roark\OneDrive\Documentos\SPP2\spp-django\venv\Lib\site-packages\mssql\base.py", line 621, in execute
    return self.cursor.execute(sql, params)
           ^^^^^^^^^^^^^^^^^^^^^^^^^^^^^^^^
django.db.utils.IntegrityError: ('23000', "[23000] [Microsoft][ODBC Driver 17 for SQL Server][SQL Server]Cannot insert the value NULL into column 'cliente', table 'SPPDB2.0.dbo.core_pedido'; column does not allow nulls. INSERT fails. (515) (SQLExecDirectW); [23000] [Microsoft][ODBC Driver 17 for SQL Server][SQL Server]The statement has been terminated. (3621)")
('23000', "[23000] [Microsoft][ODBC Driver 17 for SQL Server][SQL Server]Cannot insert the value NULL into column 'cliente', table 'SPPDB2.0.dbo.core_pedido'; column does not allow nulls. INSERT fails. (515) (SQLExecDirectW); [23000] [Microsoft][ODBC Driver 17 for SQL Server][SQL Server]The statement has been terminated. (3621)")
Traceback (most recent call last):
  File "C:\Users\Roark\OneDrive\Documentos\SPP2\spp-django\venv\Lib\site-packages\django\db\backends\utils.py", line 89, in _execute
    return self.cursor.execute(sql, params)
           ^^^^^^^^^^^^^^^^^^^^^^^^^^^^^^^^
  File "C:\Users\Roark\OneDrive\Documentos\SPP2\spp-django\venv\Lib\site-packages\mssql\base.py", line 621, in execute
    return self.cursor.execute(sql, params)
           ^^^^^^^^^^^^^^^^^^^^^^^^^^^^^^^^
pyodbc.IntegrityError: ('23000', "[23000] [Microsoft][ODBC Driver 17 for SQL Server][SQL Server]Cannot insert the value NULL into column 'cliente', table 'SPPDB2.0.dbo.core_pedido'; column does not allow nulls. INSERT fails. (515) (SQLExecDirectW); [23000] [Microsoft][ODBC Driver 17 for SQL Server][SQL Server]The statement has been terminated. (3621)")

The above exception was the direct cause of the following exception:

Traceback (most recent call last):
  File "C:\Users\Roark\OneDrive\Documentos\SPP2\spp-django\venv\Lib\site-packages\import_export\resources.py", line 748, in import_row
    self.save_instance(instance, new, using_transactions, dry_run)
  File "C:\Users\Roark\OneDrive\Documentos\SPP2\spp-django\venv\Lib\site-packages\import_export\resources.py", line 491, in save_instance
    instance.save()
  File "C:\Users\Roark\OneDrive\Documentos\SPP2\spp-django\venv\Lib\site-packages\django\db\models\base.py", line 814, in save
    self.save_base(
  File "C:\Users\Roark\OneDrive\Documentos\SPP2\spp-django\venv\Lib\site-packages\django\db\models\base.py", line 877, in save_base
    updated = self._save_table(
              ^^^^^^^^^^^^^^^^^
  File "C:\Users\Roark\OneDrive\Documentos\SPP2\spp-django\venv\Lib\site-packages\django\db\models\base.py", line 1020, in _save_table
    results = self._do_insert(
              ^^^^^^^^^^^^^^^^
  File "C:\Users\Roark\OneDrive\Documentos\SPP2\spp-django\venv\Lib\site-packages\django\db\models\base.py", line 1061, in _do_insert
    return manager._insert(
           ^^^^^^^^^^^^^^^^
  File "C:\Users\Roark\OneDrive\Documentos\SPP2\spp-django\venv\Lib\site-packages\django\db\models\manager.py", line 87, in manager_method
    return getattr(self.get_queryset(), name)(*args, **kwargs)
           ^^^^^^^^^^^^^^^^^^^^^^^^^^^^^^^^^^^^^^^^^^^^^^^^^^^
  File "C:\Users\Roark\OneDrive\Documentos\SPP2\spp-django\venv\Lib\site-packages\django\db\models\query.py", line 1805, in _insert
    return query.get_compiler(using=using).execute_sql(returning_fields)
           ^^^^^^^^^^^^^^^^^^^^^^^^^^^^^^^^^^^^^^^^^^^^^^^^^^^^^^^^^^^^^
  File "C:\Users\Roark\OneDrive\Documentos\SPP2\spp-django\venv\Lib\site-packages\django\db\models\sql\compiler.py", line 1822, in execute_sql
    cursor.execute(sql, params)
  File "C:\Users\Roark\OneDrive\Documentos\SPP2\spp-django\venv\Lib\site-packages\django\db\backends\utils.py", line 102, in execute
    return super().execute(sql, params)
           ^^^^^^^^^^^^^^^^^^^^^^^^^^^^
  File "C:\Users\Roark\OneDrive\Documentos\SPP2\spp-django\venv\Lib\site-packages\django\db\backends\utils.py", line 67, in execute
    return self._execute_with_wrappers(
           ^^^^^^^^^^^^^^^^^^^^^^^^^^^^
  File "C:\Users\Roark\OneDrive\Documentos\SPP2\spp-django\venv\Lib\site-packages\django\db\backends\utils.py", line 80, in _execute_with_wrappers
    return executor(sql, params, many, context)
           ^^^^^^^^^^^^^^^^^^^^^^^^^^^^^^^^^^^^
  File "C:\Users\Roark\OneDrive\Documentos\SPP2\spp-django\venv\Lib\site-packages\django\db\backends\utils.py", line 84, in _execute
    with self.db.wrap_database_errors:
  File "C:\Users\Roark\OneDrive\Documentos\SPP2\spp-django\venv\Lib\site-packages\django\db\utils.py", line 91, in __exit__
    raise dj_exc_value.with_traceback(traceback) from exc_value
  File "C:\Users\Roark\OneDrive\Documentos\SPP2\spp-django\venv\Lib\site-packages\django\db\backends\utils.py", line 89, in _execute
    return self.cursor.execute(sql, params)
           ^^^^^^^^^^^^^^^^^^^^^^^^^^^^^^^^
  File "C:\Users\Roark\OneDrive\Documentos\SPP2\spp-django\venv\Lib\site-packages\mssql\base.py", line 621, in execute
    return self.cursor.execute(sql, params)
           ^^^^^^^^^^^^^^^^^^^^^^^^^^^^^^^^
django.db.utils.IntegrityError: ('23000', "[23000] [Microsoft][ODBC Driver 17 for SQL Server][SQL Server]Cannot insert the value NULL into column 'cliente', table 'SPPDB2.0.dbo.core_pedido'; column does not allow nulls. INSERT fails. (515) (SQLExecDirectW); [23000] [Microsoft][ODBC Driver 17 for SQL Server][SQL Server]The statement has been terminated. (3621)")
('23000', "[23000] [Microsoft][ODBC Driver 17 for SQL Server][SQL Server]Cannot insert the value NULL into column 'cliente', table 'SPPDB2.0.dbo.core_pedido'; column does not allow nulls. INSERT fails. (515) (SQLExecDirectW); [23000] [Microsoft][ODBC Driver 17 for SQL Server][SQL Server]The statement has been terminated. (3621)")
Traceback (most recent call last):
  File "C:\Users\Roark\OneDrive\Documentos\SPP2\spp-django\venv\Lib\site-packages\django\db\backends\utils.py", line 89, in _execute
    return self.cursor.execute(sql, params)
           ^^^^^^^^^^^^^^^^^^^^^^^^^^^^^^^^
  File "C:\Users\Roark\OneDrive\Documentos\SPP2\spp-django\venv\Lib\site-packages\mssql\base.py", line 621, in execute
    return self.cursor.execute(sql, params)
           ^^^^^^^^^^^^^^^^^^^^^^^^^^^^^^^^
pyodbc.IntegrityError: ('23000', "[23000] [Microsoft][ODBC Driver 17 for SQL Server][SQL Server]Cannot insert the value NULL into column 'cliente', table 'SPPDB2.0.dbo.core_pedido'; column does not allow nulls. INSERT fails. (515) (SQLExecDirectW); [23000] [Microsoft][ODBC Driver 17 for SQL Server][SQL Server]The statement has been terminated. (3621)")

The above exception was the direct cause of the following exception:

Traceback (most recent call last):
  File "C:\Users\Roark\OneDrive\Documentos\SPP2\spp-django\venv\Lib\site-packages\import_export\resources.py", line 748, in import_row
    self.save_instance(instance, new, using_transactions, dry_run)
  File "C:\Users\Roark\OneDrive\Documentos\SPP2\spp-django\venv\Lib\site-packages\import_export\resources.py", line 491, in save_instance
    instance.save()
  File "C:\Users\Roark\OneDrive\Documentos\SPP2\spp-django\venv\Lib\site-packages\django\db\models\base.py", line 814, in save
    self.save_base(
  File "C:\Users\Roark\OneDrive\Documentos\SPP2\spp-django\venv\Lib\site-packages\django\db\models\base.py", line 877, in save_base
    updated = self._save_table(
              ^^^^^^^^^^^^^^^^^
  File "C:\Users\Roark\OneDrive\Documentos\SPP2\spp-django\venv\Lib\site-packages\django\db\models\base.py", line 1020, in _save_table
    results = self._do_insert(
              ^^^^^^^^^^^^^^^^
  File "C:\Users\Roark\OneDrive\Documentos\SPP2\spp-django\venv\Lib\site-packages\django\db\models\base.py", line 1061, in _do_insert
    return manager._insert(
           ^^^^^^^^^^^^^^^^
  File "C:\Users\Roark\OneDrive\Documentos\SPP2\spp-django\venv\Lib\site-packages\django\db\models\manager.py", line 87, in manager_method
    return getattr(self.get_queryset(), name)(*args, **kwargs)
           ^^^^^^^^^^^^^^^^^^^^^^^^^^^^^^^^^^^^^^^^^^^^^^^^^^^
  File "C:\Users\Roark\OneDrive\Documentos\SPP2\spp-django\venv\Lib\site-packages\django\db\models\query.py", line 1805, in _insert
    return query.get_compiler(using=using).execute_sql(returning_fields)
           ^^^^^^^^^^^^^^^^^^^^^^^^^^^^^^^^^^^^^^^^^^^^^^^^^^^^^^^^^^^^^
  File "C:\Users\Roark\OneDrive\Documentos\SPP2\spp-django\venv\Lib\site-packages\django\db\models\sql\compiler.py", line 1822, in execute_sql
    cursor.execute(sql, params)
  File "C:\Users\Roark\OneDrive\Documentos\SPP2\spp-django\venv\Lib\site-packages\django\db\backends\utils.py", line 102, in execute
    return super().execute(sql, params)
           ^^^^^^^^^^^^^^^^^^^^^^^^^^^^
  File "C:\Users\Roark\OneDrive\Documentos\SPP2\spp-django\venv\Lib\site-packages\django\db\backends\utils.py", line 67, in execute
    return self._execute_with_wrappers(
           ^^^^^^^^^^^^^^^^^^^^^^^^^^^^
  File "C:\Users\Roark\OneDrive\Documentos\SPP2\spp-django\venv\Lib\site-packages\django\db\backends\utils.py", line 80, in _execute_with_wrappers
    return executor(sql, params, many, context)
           ^^^^^^^^^^^^^^^^^^^^^^^^^^^^^^^^^^^^
  File "C:\Users\Roark\OneDrive\Documentos\SPP2\spp-django\venv\Lib\site-packages\django\db\backends\utils.py", line 84, in _execute
    with self.db.wrap_database_errors:
  File "C:\Users\Roark\OneDrive\Documentos\SPP2\spp-django\venv\Lib\site-packages\django\db\utils.py", line 91, in __exit__
    raise dj_exc_value.with_traceback(traceback) from exc_value
  File "C:\Users\Roark\OneDrive\Documentos\SPP2\spp-django\venv\Lib\site-packages\django\db\backends\utils.py", line 89, in _execute
    return self.cursor.execute(sql, params)
           ^^^^^^^^^^^^^^^^^^^^^^^^^^^^^^^^
  File "C:\Users\Roark\OneDrive\Documentos\SPP2\spp-django\venv\Lib\site-packages\mssql\base.py", line 621, in execute
    return self.cursor.execute(sql, params)
           ^^^^^^^^^^^^^^^^^^^^^^^^^^^^^^^^
django.db.utils.IntegrityError: ('23000', "[23000] [Microsoft][ODBC Driver 17 for SQL Server][SQL Server]Cannot insert the value NULL into column 'cliente', table 'SPPDB2.0.dbo.core_pedido'; column does not allow nulls. INSERT fails. (515) (SQLExecDirectW); [23000] [Microsoft][ODBC Driver 17 for SQL Server][SQL Server]The statement has been terminated. (3621)")
Data import failed. Please check the file format.
C:\Users\Roark\OneDrive\Documentos\SPP2\SPP-Django\core\views.py changed, reloading.
AXES: BEGIN version 6.1.0, blocking by ip_address
Watching for file changes with StatReloader
Unable to import numpy
Traceback (most recent call last):
  File "C:\Users\Roark\OneDrive\Documentos\SPP2\spp-django\venv\Lib\site-packages\mip\ndarray.py", line 6, in <module>
    import numpy as np
ModuleNotFoundError: No module named 'numpy'
Numpy not available
Traceback (most recent call last):
  File "C:\Users\Roark\OneDrive\Documentos\SPP2\spp-django\venv\Lib\site-packages\mip\model.py", line 12, in <module>
    import numpy as np
ModuleNotFoundError: No module named 'numpy'
Using Python-MIP package version 1.15.0
C:\Users\Roark\OneDrive\Documentos\SPP2\SPP-Django\core\views.py changed, reloading.
